<?xml version="1.0" ?>
    
  <robot name="staubli_tx2_60">
  <mujoco>
    <compiler balanceinertia="true" discardvisual="false" shellinertia="true" fusestatic="false" meshdir="../meshes/tx2_60/visual/" strippath="true"/>
  </mujoco>

    <link name="base_link">
      <visual>
        <origin rpy="0 0 0" xyz="0 0 0"/>
        <geometry>
          <mesh filename="package://staubli/meshes/tx2_60/visual/base_link.stl"/>
        </geometry>
        <material name="">
          <color rgba="1.0 0.6078431372549019 0.0 1.0"/>
        </material>
      </visual>
      <inertial>
        <mass value="4.0"/>
        <origin rpy="0 0 0" xyz="0.0 0.0 0.0"/>
        <inertia ixx="0.00443333156" ixy="0.0" ixz="0.0" iyy="0.00443333156" iyz="0.0" izz="0.0072"/>
      </inertial>
    </link>
    <link name="link_1">
      <visual>
        <origin rpy="0 0 0" xyz="0 0 0"/>
        <geometry>
          <mesh filename="package://staubli/meshes/tx2_60/visual/link_1.stl"/>
        </geometry>
        <material name="">
          <color rgba="1.0 0.6078431372549019 0.0 1.0"/>
        </material>
      </visual>
      <inertial>
        <mass value="3.7"/>
        <origin rpy="0 0 0" xyz="0.0 0.0 0.0"/>
        <inertia ixx="0.010267495893" ixy="0.0" ixz="0.0" iyy="0.010267495893" iyz="0.0" izz="0.00666"/>
      </inertial>
    </link>
    <link name="link_2">
      <visual>
        <origin rpy="0 0 0" xyz="0 0 0"/>
        <geometry>
          <mesh filename="package://staubli/meshes/tx2_60/visual/link_2.stl"/>
        </geometry>
        <material name="">
          <color rgba="1.0 0.6078431372549019 0.0 1.0"/>
        </material>
      </visual>
      <inertial>
        <mass value="3.7"/>
        <origin rpy="0 0 0" xyz="0.0 0.0 0.0"/>
        <inertia ixx="0.010267495893" ixy="0.0" ixz="0.0" iyy="0.010267495893" iyz="0.0" izz="0.00666"/>
      </inertial>
    </link>
    <link name="link_3">
      <visual>
        <origin rpy="0 0 0" xyz="0 0 0"/>
        <geometry>
          <mesh filename="package://staubli/meshes/tx2_60/visual/link_3.stl"/>
        </geometry>
        <material name="">
          <color rgba="1.0 0.6078431372549019 0.0 1.0"/>
        </material>
      </visual>
      <inertial>
        <mass value="8.393"/>
        <origin rpy="0 0 0" xyz="0.0 0.0 0.28"/>
        <inertia ixx="0.22689067591" ixy="0.0" ixz="0.0" iyy="0.22689067591" iyz="0.0" izz="0.0151074"/>
      </inertial>
    </link>
    <link name="link_4">
      <visual>
        <origin rpy="0 0 0" xyz="0 0 0"/>
        <geometry>
          <mesh filename="package://staubli/meshes/tx2_60/visual/link_4.stl"/>
        </geometry>
        <material name="">
          <color rgba="1.0 0.6078431372549019 0.0 1.0"/>
        </material>
      </visual>
      <inertial>
        <mass value="2.275"/>
        <origin rpy="0 0 0" xyz="0.0 0.0 0.25"/>
        <inertia ixx="0.049443313556" ixy="0.0" ixz="0.0" iyy="0.049443313556" iyz="0.0" izz="0.004095"/>
      </inertial>
    </link>
    <link name="link_5">
      <visual>
        <origin rpy="0 0 0" xyz="0 0 0"/>
        <geometry>
          <mesh filename="package://staubli/meshes/tx2_60/visual/link_5.stl"/>
        </geometry>
        <material name="">
          <color rgba="0.5294117647058824 0.5215686274509804 0.5058823529411764 1.0"/>
        </material>
      </visual>
            <inertial>
        <mass value="2.275"/>
        <origin rpy="0 0 0" xyz="0.0 0.0 0.25"/>
        <inertia ixx="0.049443313556" ixy="0.0" ixz="0.0" iyy="0.049443313556" iyz="0.0" izz="0.004095"/>
      </inertial>
    </link>
    <link name="link_6">
      <visual>
        <origin rpy="0 0 0" xyz="0 0 0"/>
        <geometry>
          <mesh filename="package://staubli/meshes/tx2_60/visual/link_6.stl"/>
        </geometry>
        <material name="">
          <color rgba="0.5294117647058824 0.5215686274509804 0.5058823529411764 1.0"/>
        </material>
      </visual>
      <inertial>
        <mass value="2.275"/>
        <origin rpy="0 0 0" xyz="0.0 0.0 0.25"/>
        <inertia ixx="0.049443313556" ixy="0.0" ixz="0.0" iyy="0.049443313556" iyz="0.0" izz="0.004095"/>
      </inertial>
    </link>
    <link name="flange">
      <visual>
        <origin rpy="0 0 0" xyz="0 0 0"/>
        <geometry>
          <mesh filename="package://staubli/meshes/tx2_60/visual/hand.stl"/>
        </geometry>
      </visual>
      <collision>
        <geometry>
          <mesh filename="package://staubli/meshes/tx2_60/visual/hand.stl"/>
        </geometry>
      </collision>
      <inertial>
        <mass value="1.219"/>
        <origin rpy="0 0 0" xyz="0.0 0.0 0.0"/>
        <inertia ixx="0.111172755531" ixy="0.0" ixz="0.0" iyy="0.111172755531" iyz="0.0" izz="0.21942"/>
      </inertial>
    </link>
    <link name="tool0_leftfinger">
      <visual>
        <origin rpy="0 0 0" xyz="0 0 0"/>
        <geometry>
          <mesh filename="package://staubli/meshes/tx2_60/visual/LeftFinger.stl"/>
        </geometry>
      </visual>
      <collision>
        <geometry>
          <mesh filename="package://staubli/meshes/tx2_60/visual/LeftFinger.stl"/>
        </geometry>
      </collision>
      <inertial>
        <mass value="0.1"/>
        <origin xyz="-0.01 0 0"/>
        <inertia ixx="0.000018" ixy="0" ixz="0" iyy="0.000025" iyz="0" izz="0.000025"/>
      </inertial>
    </link>
    <link name="tool0_rightfinger">
      <visual>
        <origin rpy="0 0 0" xyz="0 0 0"/>
        <geometry>
          <mesh filename="package://staubli/meshes/tx2_60/visual/RightFinger.stl"/>
        </geometry>
      </visual>
      <collision>
        <geometry>
          <mesh filename="package://staubli/meshes/tx2_60/visual/RightFinger.stl"/>
        </geometry>
      </collision>
      <inertial>
        <mass value="0.1"/>
        <origin xyz="-0.01 0 0"/>
        <inertia ixx="0.000018" ixy="0" ixz="0" iyy="0.000025" iyz="0" izz="0.000025"/>
      </inertial>
    </link>
    <!-- joints: main serial chain -->
    <joint name="joint_1" type="revolute">
      <origin rpy="0 0 0" xyz="0 0 0.375"/>
      <parent link="base_link"/>
      <child link="link_1"/>
      <axis xyz="0 0 -1"/>
      <!-- from Staubli instruction manual:
        (1) effort limit = 126 Nm if floor mounted
        (2) effort limit = 40 Nm if wall mounted -->
      <!-- nominal velocity limits are used -->
      <limit effort="126.0" lower="0" upper="6.2831853071795864" velocity="7.592182246175334"/>
    </joint>
    <joint name="joint_2" type="revolute">
      <origin rpy="0 0 0" xyz="0 0 0"/>
      <parent link="link_1"/>
      <child link="link_2"/>
      <axis xyz="0 1 0"/>
      <!-- nominal velocity limits are used -->
      <limit effort="47.0" lower="-2.2252947962927703" upper="2.2252947962927703" velocity="6.719517620178169"/>
    </joint>
    <joint name="joint_3" type="revolute">
      <origin rpy="0 0 0" xyz="0 0.02 0.29"/>
      <parent link="link_2"/>
      <child link="link_3"/>
      <axis xyz="0 1 0"/>
      <!-- nominal velocity limits are used -->
      <limit effort="32.0" lower="-2.6616271092913526" upper="2.6616271092913526" velocity="8.726646259971648"/>
    </joint>
    <joint name="joint_4" type="revolute">
      <origin rpy="0 0 3.141592653589793" xyz="0 0 0"/>
      <parent link="link_3"/>
      <child link="link_4"/>
      <axis xyz="0 0 1"/>
      <!-- nominal velocity limits are used -->
      <limit effort="7.0" lower="-4.71238898038469" upper="4.71238898038469" velocity="17.36602605734358"/>
    </joint>
    <joint name="joint_5" type="revolute">
      <origin rpy="0 0 0" xyz="0 0 0.31"/>
      <parent link="link_4"/>
      <child link="link_5"/>
      <axis xyz="0 1 0"/>
      <!-- nominal velocity limits are used -->
      <limit effort="8.0" lower="-2.111848394913139" upper="2.3125612588924866" velocity="18.58775653373961"/>
    </joint>
    <joint name="joint_6" type="revolute">
      <origin rpy="0 0 0" xyz="0 0 0.07"/>
      <parent link="link_5"/>
      <child link="link_6"/>
      <axis xyz="0 0 1"/>
      <!-- nominal velocity limits are used -->
      <limit effort="2.0" lower="-4.71238898038469" upper="4.71238898038469" velocity="25.220007691318063"/>
    </joint>
    <!-- ROS-Industrial 'base' frame: base_link to Staubli World Coordinates transform -->
    <!-- ROS-Industrial 'flange' frame: attachment point for EEF models -->
    <joint name="joint_6_flange" type="fixed">
      <origin rpy="0 0 0" xyz="0 0 0.01"/>
      <parent link="link_6"/>
      <child link="flange"/>
    </joint>
    <!-- ROS-Industrial 'tool0' frame: all-zeros tool frame -->
    <joint name="tool0_leftfinger" type="prismatic">
      <parent link="flange"/>
      <child link="tool0_leftfinger"/>
      <origin rpy="0.0174533 0 0" xyz="0 -0.0073 0.075"/>
      <axis xyz="0 -1 0"/>
      <limit effort="20" lower="0.0" upper="0.008" velocity="0.2"/>
    </joint>
    <joint name="tool0_rightfinger" type="prismatic">
      <parent link="flange"/>
      <child link="tool0_rightfinger"/>
      <origin rpy="-0.0174533 0 0" xyz="0 0.0073 0.075"/>
      <axis xyz="0 1 0"/>
      <limit effort="20" lower="0.0" upper="0.008" velocity="0.2"/>
    </joint>
    <link name="gripper_center"/>
    <joint name="gripper_center_joint" type="fixed">
      <origin rpy="0 0 0" xyz="0.0 -0.00791 0.035"/>
      <parent link="tool0_rightfinger"/>
      <child link="gripper_center"/>
    </joint>
  </robot>

